Workbook

Sheet Elementi
A1: Element | B1: Type | C1: Sub Type | D1: Material | E1: Property | F1: B-Angle ([deg]) | G1: Node1 | H1: Node2 | I1: Node3 | J1: Node4 | K1: Node5 | L1: Node6 | M1: Node7 | N1: Node8 | O1: Kind | P1: Hook/Gap (cm) | Q1: Lu (cm) | R1: Tension (kgf) | S1: Allow. Comp/Tens (kgf) | T1: Use Limit | U1: Comp/Tens Limit (kgf)
A2: 1 | B2: BEAM | D2: 1 | E2: 1 | F2: 0 | G2: 2 | H2: 1 | I2: 0 | J2: 0 | K2: 0 | L2: 0 | M2: 0 | N2: 0 | O2: Lu | P2: 0 | Q2: 0 | R2: 0 | S2: 0 | T2: 0 | U2: 0
A3: 2 | B3: BEAM | D3: 1 | E3: 1 | F3: 0 | G3: 3 | H3: 2 | I3: 0 | J3: 0 | K3: 0 | L3: 0 | M3: 0 | N3: 0 | O3: Lu | P3: 0 | Q3: 0 | R3: 0 | S3: 0 | T3: 0 | U3: 0
A4: 3 | B4: BEAM | D4: 1 | E4: 1 | F4: 0 | G4: 4 | H4: 3 | I4: 0 | J4: 0 | K4: 0 | L4: 0 | M4: 0 | N4: 0 | O4: Lu | P4: 0 | Q4: 0 | R4: 0 | S4: 0 | T4: 0 | U4: 0
A5: 4 | B5: BEAM | D5: 1 | E5: 1 | F5: 0 | G5: 5 | H5: 4 | I5: 0 | J5: 0 | K5: 0 | L5: 0 | M5: 0 | N5: 0 | O5: Lu | P5: 0 | Q5: 0 | R5: 0 | S5: 0 | T5: 0 | U5: 0
A6: 5 | B6: BEAM | D6: 1 | E6: 1 | F6: 0 | G6: 6 | H6: 5 | I6: 0 | J6: 0 | K6: 0 | L6: 0 | M6: 0 | N6: 0 | O6: Lu | P6: 0 | Q6: 0 | R6: 0 | S6: 0 | T6: 0 | U6: 0
A7: 6 | B7: BEAM | D7: 1 | E7: 1 | F7: 0 | G7: 7 | H7: 6 | I7: 0 | J7: 0 | K7: 0 | L7: 0 | M7: 0 | N7: 0 | O7: Lu | P7: 0 | Q7: 0 | R7: 0 | S7: 0 | T7: 0 | U7: 0
A8: 7 | B8: BEAM | D8: 1 | E8: 1 | F8: 0 | G8: 8 | H8: 7 | I8: 0 | J8: 0 | K8: 0 | L8: 0 | M8: 0 | N8: 0 | O8: Lu | P8: 0 | Q8: 0 | R8: 0 | S8: 0 | T8: 0 | U8: 0
A9: 8 | B9: BEAM | D9: 1 | E9: 1 | F9: 0 | G9: 9 | H9: 8 | I9: 0 | J9: 0 | K9: 0 | L9: 0 | M9: 0 | N9: 0 | O9: Lu | P9: 0 | Q9: 0 | R9: 0 | S9: 0 | T9: 0 | U9: 0
A10: 9 | B10: BEAM | D10: 1 | E10: 1 | F10: 0 | G10: 10 | H10: 9 | I10: 0 | J10: 0 | K10: 0 | L10: 0 | M10: 0 | N10: 0 | O10: Lu | P10: 0 | Q10: 0 | R10: 0 | S10: 0 | T10: 0 | U10: 0
A11: 10 | B11: BEAM | D11: 1 | E11: 1 | F11: 0 | G11: 11 | H11: 10 | I11: 0 | J11: 0 | K11: 0 | L11: 0 | M11: 0 | N11: 0 | O11: Lu | P11: 0 | Q11: 0 | R11: 0 | S11: 0 | T11: 0 | U11: 0
A12: 11 | B12: BEAM | D12: 1 | E12: 1 | F12: 0 | G12: 12 | H12: 11 | I12: 0 | J12: 0 | K12: 0 | L12: 0 | M12: 0 | N12: 0 | O12: Lu | P12: 0 | Q12: 0 | R12: 0 | S12: 0 | T12: 0 | U12: 0
A13: 12 | B13: BEAM | D13: 1 | E13: 1 | F13: 0 | G13: 13 | H13: 12 | I13: 0 | J13: 0 | K13: 0 | L13: 0 | M13: 0 | N13: 0 | O13: Lu | P13: 0 | Q13: 0 | R13: 0 | S13: 0 | T13: 0 | U13: 0
... A861: 929 | B861: BEAM | D861: 1 | E861: 1 | F861: 0 | G861: 930 | H861: 929 | I861: 0 | J861: 0 | K861: 0 | L861: 0 | M861: 0 | N861: 0 | O861: Lu | P861: 0 | Q861: 0 | R861: 0 | S861: 0 | T861: 0 | U861: 0

Sheet Nodi
A1: Node | B1: X | C1: Y | D1: Z
A2: 500 | B2: 0.942121 | C2: 163.90455 | D2: 0
A3: 501 | B3: -0.060101 | C3: 163.92265 | D3: 0
A4: 502 | B4: -1.059941 | C4: 163.94071 | D4: 0
A5: 503 | B5: -2.064893 | C5: 163.95885 | D5: 0
A6: 504 | B6: -3.064731 | C6: 163.97691 | D6: 0
A7: 505 | B7: -4.068338 | C7: 163.99503 | D7: 0
A8: 506 | B8: -5.071018 | C8: 164.01314 | D8: 0
A9: 507 | B9: -6.075336 | C9: 164.03128 | D9: 0
A10: 508 | B10: -7.075173 | C10: 164.04933 | D10: 0
A11: 509 | B11: -8.081598 | C11: 164.06751 | D11: 0
A12: 510 | B12: -9.081438 | C12: 164.08556 | D12: 0
A13: 511 | B13: -10.08883 | C13: 164.10375 | D13: 0
... A432: 930 | B432: -355.18367 | C432: 9.178216 | D432: 0

Sheet disp
A1: Node | B1: Load | C1: DX (mm) | D1: DY (mm) | E1: DZ (mm) | F1: RX ([rad]) | G1: RY ([rad]) | H1: RZ ([rad])
A2: 500 | B2: Tandem_Max_sx(min) | C2: -0.191668 | D2: -0.074707 | E2: 0 | F2: -6e-06 | G2: -0.000282 | H2: -1.8e-05
A3: 512 | B3: Tandem_Max_sx(min) | C3: -0.174077 | D3: -0.52601 | E3: -3.214996 | F3: -0.000266 | G3: -0.000194 | H3: -8e-06
A4: 524 | B4: Tandem_Max_sx(min) | C4: -0.145653 | D4: -0.775081 | E4: -4.615713 | F4: -0.000429 | G4: -5.8e-05 | H4: -8e-06
A5: 535 | B5: Tandem_Max_sx(min) | C5: -0.110763 | D5: -0.751493 | E5: -3.884537 | F5: -0.000449 | G5: -1.5e-05 | H5: -1.5e-05
A6: 547 | B6: Tandem_Max_sx(min) | C6: -0.090815 | D6: -0.426927 | E6: -1.497369 | F6: -0.000178 | G6: -0.000161 | H6: -3.4e-05
A7: 554 | B7: Tandem_Max_sx(min) | C7: -0.15356 | D7: -0.461018 | E7: 0 | F7: -9e-06 | G7: -0.000216 | H7: -4.5e-05
A8: 560 | B8: Tandem_Max_sx(min) | C8: -0.188307 | D8: -0.744364 | E8: -1.498681 | F8: -0.000167 | G8: -0.000245 | H8: -5.4e-05
A9: 573 | B9: Tandem_Max_sx(min) | C9: -0.117712 | D9: -1.240333 | E9: -4.310815 | F9: -0.000389 | G9: -0.000157 | H9: -1.6e-05
A10: 586 | B10: Tandem_Max_sx(min) | C10: -0.14273 | D10: -1.237704 | E10: -5.477472 | F10: -0.000382 | G10: -5.6e-05 | H10: -1.2e-05
A11: 599 | B11: Tandem_Max_sx(min) | C11: -0.156389 | D11: -1.107973 | E11: -4.194361 | F11: -0.000394 | G11: -7.2e-05 | H11: -1.9e-05
A12: 612 | B12: Tandem_Max_sx(min) | C12: -0.146685 | D12: -0.524924 | E12: -1.434744 | F12: -0.000143 | G12: -0.000159 | H12: -2.4e-05
A13: 619 | B13: Tandem_Max_sx(min) | C13: -0.136143 | D13: -0.265835 | E13: 0 | F13: -3.8e-05 | G13: -0.000205 | H13: -4.5e-05
... A42: 930 | B42: Tandem_Max_sx(min) | C42: -1.000586 | D42: -0.330444 | E42: 0 | F42: -0.000184 | G42: -5.9e-05 | H42: -3e-05
A43: =A2 -> 500 | B43: Distr_Ecc_sx(min) | C43: -0.273858 | D43: -0.014147 | E43: 0 | F43: -7e-06 | G43: -0.000318 | H43: -2.3e-05
A44: =A3 -> 512 | B44: Distr_Ecc_sx(min) | C44: -0.237624 | D44: -0.670272 | E44: -3.588767 | F44: -0.000451 | G44: -0.000208 | H44: -1.6e-05
A45: =A4 -> 524 | B45: Distr_Ecc_sx(min) | C45: -0.163205 | D45: -1.022457 | E45: -5.093341 | F45: -0.000728 | G45: -4.8e-05 | H45: -1.2e-05
A46: =A5 -> 535 | B46: Distr_Ecc_sx(min) | C46: -0.116343 | D46: -1.112486 | E46: -4.569301 | F46: -0.000758 | G46: -1.9e-05 | H46: -1e-05
A47: =A6 -> 547 | B47: Distr_Ecc_sx(min) | C47: -0.107138 | D47: -0.986205 | E47: -1.910407 | F47: -0.000301 | G47: -0.000196 | H47: -5.6e-05
A48: =A7 -> 554 | B48: Distr_Ecc_sx(min) | C48: -0.20254 | D48: -0.780655 | E48: 0 | F48: -1e-05 | G48: -0.000269 | H48: -7.6e-05
A49: =A8 -> 560 | B49: Distr_Ecc_sx(min) | C49: -0.257203 | D49: -1.187753 | E49: -1.879556 | F49: -0.000391 | G49: -0.000311 | H49: -8.2e-05
A50: =A9 -> 573 | B50: Distr_Ecc_sx(min) | C50: -0.199864 | D50: -1.797372 | E50: -5.400758 | F50: -0.001003 | G50: -0.000211 | H50: -3.4e-05
A51: =A10 -> 586 | B51: Distr_Ecc_sx(min) | C51: -0.239562 | D51: -1.803048 | E51: -6.845908 | F51: -0.00113 | G51: -0.000114 | H51: -2.6e-05
A52: =A11 -> 599 | B52: Distr_Ecc_sx(min) | C52: -0.262485 | D52: -1.577173 | E52: -5.64714 | F52: -0.000958 | G52: -0.000202 | H52: -2.2e-05
A53: =A12 -> 612 | B53: Distr_Ecc_sx(min) | C53: -0.267927 | D53: -0.989727 | E53: -2.098992 | F53: -0.000318 | G53: -0.000269 | H53: -5.2e-05
A54: =A13 -> 619 | B54: Distr_Ecc_sx(min) | C54: -0.289575 | D54: -0.694814 | E54: 0 | F54: -5.4e-05 | G54: -0.000314 | H54: -6.8e-05
... A329: =A288 -> 930 | B329: E2-Ritiro | C329: 26.768083 | D329: -3.636261 | E329: 0 | F329: -0.000769 | G329: 0.001802 | H329: 0.000268

Sheet OUTput_Monta_TrSx
E2: Monta di officina [mm]
C3: X [m] | D3: X [m] | F3: Conci | H3: Nodo | I3: G | J3: P | K3: Tandem | L3: Distr | M3: 0.25M | N3: Z | O3: Monta | P3: Concio | T3: Load case:
C4: =_xlfn.XLOOKUP(H4,Nodi!$A:$A,Nodi!$B:$B) -> -355.18367 | D4: =C4-$C$4 -> 0 | E4: SP1 | G4: CS-01 | H4: 930 | I4: {=_xlfn.XLOOKUP(H4&$T$11,disp!A:A&disp!B:B,disp!E:E)} -> 0 | J4: {=_xlfn.XLOOKUP(H4&$T$12,disp!A:A&disp!B:B,disp!E:E)} -> 0 | K4: {=(MIN(INDEX(disp!$A$2:$H$274,MATCH(1,(disp!$A$2:$A$285=OUTput_Monta_TrSx!H4)*(disp!$B$2:$B$274="Tandem_Max(min)"),0),5),INDEX(disp!$A$2:$H$274,MATCH(1,(disp!$A$2:$A$285=OUTput_Monta_TrSx!H4)*(disp!$B$2:$B$274="tandem_Ecc(min)"),0),5)))} -> #N/A | L4: {=MIN(INDEX(disp!$A$2:$H$274,MATCH(1,(disp!$A$2:$A$285=OUTput_Monta_TrSx!H4)*(disp!$B$2:$B$274="Distr_Ecc(min)"),0),5),INDEX(disp!$A$2:$H$274,MATCH(1,(disp!$A$2:$A$285=OUTput_Monta_TrSx!H4)*(disp!$B$2:$B$274="Distr_Max(min)"),0),5))} -> #N/A | M4: {=0.25*(_xlfn.XLOOKUP(H4&$T$6,disp!A:A&disp!B:B,disp!E:E)+_xlfn.XLOOKUP(H4&$T$9,disp!A:A&disp!B:B,disp!E:E))+0.25*(_xlfn.XLOOKUP(H4&$T$7,disp!A:A&disp!B:B,disp!E:E)+_xlfn.XLOOKUP(H4&$T$8,disp!A:A&disp!B:B,disp!E:E)+_xlfn.XLOOKUP(H4&$T$10,disp!A:A&disp!B:B,disp!E:E))} -> 0 | N4: =ROUND(I4+J4+M4,0) -> 0 | O4: =ABS(_xlfn.FLOOR.MATH(N4,5)) -> 0 | P4: =LOOKUP(H4,Elementi!$H:$H,Elementi!$E:$E) -> 1 | T4: {=_xlfn.UNIQUE(disp!B:B,FALSE,FALSE)} -> Load
C5: =_xlfn.XLOOKUP(H5,Nodi!$A:$A,Nodi!$B:$B) -> -347.54701 | D5: =C5-$C$4 -> 7.636655 | F5: CS-02 | H5: 918 | I5: {=_xlfn.XLOOKUP(H5&$T$11,disp!A:A&disp!B:B,disp!E:E)} -> -13.401658 | J5: {=_xlfn.XLOOKUP(H5&$T$12,disp!A:A&disp!B:B,disp!E:E)} -> -13.996729 | K5: {=(MIN(INDEX(disp!$A$2:$H$274,MATCH(1,(disp!$A$2:$A$285=OUTput_Monta_TrSx!H5)*(disp!$B$2:$B$274="Tandem_Max(min)"),0),5),INDEX(disp!$A$2:$H$274,MATCH(1,(disp!$A$2:$A$285=OUTput_Monta_TrSx!H5)*(disp!$B$2:$B$274="tandem_Ecc(min)"),0),5)))} -> #N/A | L5: {=MIN(INDEX(disp!$A$2:$H$274,MATCH(1,(disp!$A$2:$A$285=OUTput_Monta_TrSx!H5)*(disp!$B$2:$B$274="Distr_Ecc(min)"),0),5),INDEX(disp!$A$2:$H$274,MATCH(1,(disp!$A$2:$A$285=OUTput_Monta_TrSx!H5)*(disp!$B$2:$B$274="Distr_Max(min)"),0),5))} -> #N/A | M5: {=0.25*(_xlfn.XLOOKUP(H5&$T$6,disp!A:A&disp!B:B,disp!E:E)+_xlfn.XLOOKUP(H5&$T$9,disp!A:A&disp!B:B,disp!E:E))+0.25*(_xlfn.XLOOKUP(H5&$T$7,disp!A:A&disp!B:B,disp!E:E)+_xlfn.XLOOKUP(H5&$T$8,disp!A:A&disp!B:B,disp!E:E)+_xlfn.XLOOKUP(H5&$T$10,disp!A:A&disp!B:B,disp!E:E))} -> -16.430929 | N5: =ROUND(I5+J5+M5,0) -> -44 | O5: =ABS(_xlfn.FLOOR.MATH(N5,5)) -> 45 | P5: =LOOKUP(H5,Elementi!$H:$H,Elementi!$E:$E) -> 1 | T5: Tandem_Max_sx(min)
C6: =_xlfn.XLOOKUP(H6,Nodi!$A:$A,Nodi!$B:$B) -> -340.30557 | D6: =C6-$C$4 -> 14.878099 | F6: C2 | G6: CS-03 | H6: 907 | I6: {=_xlfn.XLOOKUP(H6&$T$11,disp!A:A&disp!B:B,disp!E:E)} -> -16.113793 | J6: {=_xlfn.XLOOKUP(H6&$T$12,disp!A:A&disp!B:B,disp!E:E)} -> -16.005385 | K6: {=(MIN(INDEX(disp!$A$2:$H$274,MATCH(1,(disp!$A$2:$A$285=OUTput_Monta_TrSx!H6)*(disp!$B$2:$B$274="Tandem_Max(min)"),0),5),INDEX(disp!$A$2:$H$274,MATCH(1,(disp!$A$2:$A$285=OUTput_Monta_TrSx!H6)*(disp!$B$2:$B$274="tandem_Ecc(min)"),0),5)))} -> #N/A | L6: {=MIN(INDEX(disp!$A$2:$H$274,MATCH(1,(disp!$A$2:$A$285=OUTput_Monta_TrSx!H6)*(disp!$B$2:$B$274="Distr_Ecc(min)"),0),5),INDEX(disp!$A$2:$H$274,MATCH(1,(disp!$A$2:$A$285=OUTput_Monta_TrSx!H6)*(disp!$B$2:$B$274="Distr_Max(min)"),0),5))} -> #N/A | M6: {=0.25*(_xlfn.XLOOKUP(H6&$T$6,disp!A:A&disp!B:B,disp!E:E)+_xlfn.XLOOKUP(H6&$T$9,disp!A:A&disp!B:B,disp!E:E))+0.25*(_xlfn.XLOOKUP(H6&$T$7,disp!A:A&disp!B:B,disp!E:E)+_xlfn.XLOOKUP(H6&$T$8,disp!A:A&disp!B:B,disp!E:E)+_xlfn.XLOOKUP(H6&$T$10,disp!A:A&disp!B:B,disp!E:E))} -> -21.028131 | N6: =ROUND(I6+J6+M6,0) -> -53 | O6: =ABS(_xlfn.FLOOR.MATH(N6,5)) -> 55 | P6: =LOOKUP(H6,Elementi!$H:$H,Elementi!$E:$E) -> 2 | T6: Distr_Ecc_sx(min)
C7: =_xlfn.XLOOKUP(H7,Nodi!$A:$A,Nodi!$B:$B) -> -333.52134 | D7: =C7-$C$4 -> 21.662331 | F7: CS-04 | G7: C3 | H7: 897 | I7: {=_xlfn.XLOOKUP(H7&$T$11,disp!A:A&disp!B:B,disp!E:E)} -> -11.274527 | J7: {=_xlfn.XLOOKUP(H7&$T$12,disp!A:A&disp!B:B,disp!E:E)} -> -9.738489 | K7: {=(MIN(INDEX(disp!$A$2:$H$274,MATCH(1,(disp!$A$2:$A$285=OUTput_Monta_TrSx!H7)*(disp!$B$2:$B$274="Tandem_Max(min)"),0),5),INDEX(disp!$A$2:$H$274,MATCH(1,(disp!$A$2:$A$285=OUTput_Monta_TrSx!H7)*(disp!$B$2:$B$274="tandem_Ecc(min)"),0),5)))} -> #N/A | L7: {=MIN(INDEX(disp!$A$2:$H$274,MATCH(1,(disp!$A$2:$A$285=OUTput_Monta_TrSx!H7)*(disp!$B$2:$B$274="Distr_Ecc(min)"),0),5),INDEX(disp!$A$2:$H$274,MATCH(1,(disp!$A$2:$A$285=OUTput_Monta_TrSx!H7)*(disp!$B$2:$B$274="Distr_Max(min)"),0),5))} -> #N/A | M7: {=0.25*(_xlfn.XLOOKUP(H7&$T$6,disp!A:A&disp!B:B,disp!E:E)+_xlfn.XLOOKUP(H7&$T$9,disp!A:A&disp!B:B,disp!E:E))+0.25*(_xlfn.XLOOKUP(H7&$T$7,disp!A:A&disp!B:B,disp!E:E)+_xlfn.XLOOKUP(H7&$T$8,disp!A:A&disp!B:B,disp!E:E)+_xlfn.XLOOKUP(H7&$T$10,disp!A:A&disp!B:B,disp!E:E))} -> -16.024482 | N7: =ROUND(I7+J7+M7,0) -> -37 | O7: =ABS(_xlfn.FLOOR.MATH(N7,5)) -> 40 | P7: =LOOKUP(H7,Elementi!$H:$H,Elementi!$E:$E) -> 3 | T7: Distr_max_sx(min)
C8: =_xlfn.XLOOKUP(H8,Nodi!$A:$A,Nodi!$B:$B) -> -325.84909 | D8: =C8-$C$4 -> 29.334581 | E8: P01 | F8: C2 | G8: CS-05 | H8: 886 | I8: {=_xlfn.XLOOKUP(H8&$T$11,disp!A:A&disp!B:B,disp!E:E)} -> -2.53015 | J8: {=_xlfn.XLOOKUP(H8&$T$12,disp!A:A&disp!B:B,disp!E:E)} -> -1.881795 | K8: {=(MIN(INDEX(disp!$A$2:$H$274,MATCH(1,(disp!$A$2:$A$285=OUTput_Monta_TrSx!H8)*(disp!$B$2:$B$274="Tandem_Max(min)"),0),5),INDEX(disp!$A$2:$H$274,MATCH(1,(disp!$A$2:$A$285=OUTput_Monta_TrSx!H8)*(disp!$B$2:$B$274="tandem_Ecc(min)"),0),5)))} -> #N/A | L8: {=MIN(INDEX(disp!$A$2:$H$274,MATCH(1,(disp!$A$2:$A$285=OUTput_Monta_TrSx!H8)*(disp!$B$2:$B$274="Distr_Ecc(min)"),0),5),INDEX(disp!$A$2:$H$274,MATCH(1,(disp!$A$2:$A$285=OUTput_Monta_TrSx!H8)*(disp!$B$2:$B$274="Distr_Max(min)"),0),5))} -> #N/A | M8: {=0.25*(_xlfn.XLOOKUP(H8&$T$6,disp!A:A&disp!B:B,disp!E:E)+_xlfn.XLOOKUP(H8&$T$9,disp!A:A&disp!B:B,disp!E:E))+0.25*(_xlfn.XLOOKUP(H8&$T$7,disp!A:A&disp!B:B,disp!E:E)+_xlfn.XLOOKUP(H8&$T$8,disp!A:A&disp!B:B,disp!E:E)+_xlfn.XLOOKUP(H8&$T$10,disp!A:A&disp!B:B,disp!E:E))} -> -5.2584218 | N8: =ROUND(I8+J8+M8,0) -> -10 | O8: 0 | P8: =LOOKUP(H8,Elementi!$H:$H,Elementi!$E:$E) -> 4 | T8: Tandem Max sx piazzola(min)
C9: =_xlfn.XLOOKUP(H9,Nodi!$A:$A,Nodi!$B:$B) -> -321.53378 | D9: =C9-$C$4 -> 33.649891 | H9: 879 | I9: {=_xlfn.XLOOKUP(H9&$T$11,disp!A:A&disp!B:B,disp!E:E)} -> 0 | J9: {=_xlfn.XLOOKUP(H9&$T$12,disp!A:A&disp!B:B,disp!E:E)} -> 0 | K9: {=(MIN(INDEX(disp!$A$2:$H$274,MATCH(1,(disp!$A$2:$A$285=OUTput_Monta_TrSx!H9)*(disp!$B$2:$B$274="Tandem_Max(min)"),0),5),INDEX(disp!$A$2:$H$274,MATCH(1,(disp!$A$2:$A$285=OUTput_Monta_TrSx!H9)*(disp!$B$2:$B$274="tandem_Ecc(min)"),0),5)))} -> #N/A | L9: {=MIN(INDEX(disp!$A$2:$H$274,MATCH(1,(disp!$A$2:$A$285=OUTput_Monta_TrSx!H9)*(disp!$B$2:$B$274="Distr_Ecc(min)"),0),5),INDEX(disp!$A$2:$H$274,MATCH(1,(disp!$A$2:$A$285=OUTput_Monta_TrSx!H9)*(disp!$B$2:$B$274="Distr_Max(min)"),0),5))} -> #N/A | M9: {=0.25*(_xlfn.XLOOKUP(H9&$T$6,disp!A:A&disp!B:B,disp!E:E)+_xlfn.XLOOKUP(H9&$T$9,disp!A:A&disp!B:B,disp!E:E))+0.25*(_xlfn.XLOOKUP(H9&$T$7,disp!A:A&disp!B:B,disp!E:E)+_xlfn.XLOOKUP(H9&$T$8,disp!A:A&disp!B:B,disp!E:E)+_xlfn.XLOOKUP(H9&$T$10,disp!A:A&disp!B:B,disp!E:E))} -> 0 | N9: =ROUND(I9+J9+M9,0) -> 0 | O9: =ABS(_xlfn.FLOOR.MATH(N9,5)) -> 0 | P9: =LOOKUP(H9,Elementi!$H:$H,Elementi!$E:$E) -> 5 | T9: Distr_ecc_sx_piazzola(min)
C10: =_xlfn.XLOOKUP(H10,Nodi!$A:$A,Nodi!$B:$B) -> -317.23603 | D10: =C10-$C$4 -> 37.947633 | F10: CS-06 | H10: 873 | I10: {=_xlfn.XLOOKUP(H10&$T$11,disp!A:A&disp!B:B,disp!E:E)} -> -2.201204 | J10: {=_xlfn.XLOOKUP(H10&$T$12,disp!A:A&disp!B:B,disp!E:E)} -> 0.677978 | K10: {=(MIN(INDEX(disp!$A$2:$H$274,MATCH(1,(disp!$A$2:$A$285=OUTput_Monta_TrSx!H10)*(disp!$B$2:$B$274="Tandem_Max(min)"),0),5),INDEX(disp!$A$2:$H$274,MATCH(1,(disp!$A$2:$A$285=OUTput_Monta_TrSx!H10)*(disp!$B$2:$B$274="tandem_Ecc(min)"),0),5)))} -> #N/A | L10: {=MIN(INDEX(disp!$A$2:$H$274,MATCH(1,(disp!$A$2:$A$285=OUTput_Monta_TrSx!H10)*(disp!$B$2:$B$274="Distr_Ecc(min)"),0),5),INDEX(disp!$A$2:$H$274,MATCH(1,(disp!$A$2:$A$285=OUTput_Monta_TrSx!H10)*(disp!$B$2:$B$274="Distr_Max(min)"),0),5))} -> #N/A | M10: {=0.25*(_xlfn.XLOOKUP(H10&$T$6,disp!A:A&disp!B:B,disp!E:E)+_xlfn.XLOOKUP(H10&$T$9,disp!A:A&disp!B:B,disp!E:E))+0.25*(_xlfn.XLOOKUP(H10&$T$7,disp!A:A&disp!B:B,disp!E:E)+_xlfn.XLOOKUP(H10&$T$8,disp!A:A&disp!B:B,disp!E:E)+_xlfn.XLOOKUP(H10&$T$10,disp!A:A&disp!B:B,disp!E:E))} -> -4.284039 | N10: =ROUND(I10+J10+M10,0) -> -6 | O10: 0 | P10: =LOOKUP(H10,Elementi!$H:$H,Elementi!$E:$E) -> 5 | T10: G1
C11: =_xlfn.XLOOKUP(H11,Nodi!$A:$A,Nodi!$B:$B) -> -308.35538 | D11: =C11-$C$4 -> 46.828287 | G11: CS-07 | H11: 860 | I11: {=_xlfn.XLOOKUP(H11&$T$11,disp!A:A&disp!B:B,disp!E:E)} -> -11.341973 | J11: {=_xlfn.XLOOKUP(H11&$T$12,disp!A:A&disp!B:B,disp!E:E)} -> -3.913056 | K11: {=(MIN(INDEX(disp!$A$2:$H$274,MATCH(1,(disp!$A$2:$A$285=OUTput_Monta_TrSx!H11)*(disp!$B$2:$B$274="Tandem_Max(min)"),0),5),INDEX(disp!$A$2:$H$274,MATCH(1,(disp!$A$2:$A$285=OUTput_Monta_TrSx!H11)*(disp!$B$2:$B$274="tandem_Ecc(min)"),0),5)))} -> #N/A | L11: {=MIN(INDEX(disp!$A$2:$H$274,MATCH(1,(disp!$A$2:$A$285=OUTput_Monta_TrSx!H11)*(disp!$B$2:$B$274="Distr_Ecc(min)"),0),5),INDEX(disp!$A$2:$H$274,MATCH(1,(disp!$A$2:$A$285=OUTput_Monta_TrSx!H11)*(disp!$B$2:$B$274="Distr_Max(min)"),0),5))} -> #N/A | M11: {=0.25*(_xlfn.XLOOKUP(H11&$T$6,disp!A:A&disp!B:B,disp!E:E)+_xlfn.XLOOKUP(H11&$T$9,disp!A:A&disp!B:B,disp!E:E))+0.25*(_xlfn.XLOOKUP(H11&$T$7,disp!A:A&disp!B:B,disp!E:E)+_xlfn.XLOOKUP(H11&$T$8,disp!A:A&disp!B:B,disp!E:E)+_xlfn.XLOOKUP(H11&$T$10,disp!A:A&disp!B:B,disp!E:E))} -> -15.979414 | N11: =ROUND(I11+J11+M11,0) -> -31 | O11: =ABS(_xlfn.FLOOR.MATH(N11,5)) -> 35 | P11: =LOOKUP(H11,Elementi!$H:$H,Elementi!$E:$E) -> 6 | T11: G2
C12: =_xlfn.XLOOKUP(H12,Nodi!$A:$A,Nodi!$B:$B) -> -299.21414 | D12: =C12-$C$4 -> 55.969531 | F12: CS-08 | H12: 847 | I12: {=_xlfn.XLOOKUP(H12&$T$11,disp!A:A&disp!B:B,disp!E:E)} -> -16.037607 | J12: {=_xlfn.XLOOKUP(H12&$T$12,disp!A:A&disp!B:B,disp!E:E)} -> -8.706697 | K12: {=(MIN(INDEX(disp!$A$2:$H$274,MATCH(1,(disp!$A$2:$A$285=OUTput_Monta_TrSx!H12)*(disp!$B$2:$B$274="Tandem_Max(min)"),0),5),INDEX(disp!$A$2:$H$274,MATCH(1,(disp!$A$2:$A$285=OUTput_Monta_TrSx!H12)*(disp!$B$2:$B$274="tandem_Ecc(min)"),0),5)))} -> #N/A | L12: {=MIN(INDEX(disp!$A$2:$H$274,MATCH(1,(disp!$A$2:$A$285=OUTput_Monta_TrSx!H12)*(disp!$B$2:$B$274="Distr_Ecc(min)"),0),5),INDEX(disp!$A$2:$H$274,MATCH(1,(disp!$A$2:$A$285=OUTput_Monta_TrSx!H12)*(disp!$B$2:$B$274="Distr_Max(min)"),0),5))} -> #N/A | M12: {=0.25*(_xlfn.XLOOKUP(H12&$T$6,disp!A:A&disp!B:B,disp!E:E)+_xlfn.XLOOKUP(H12&$T$9,disp!A:A&disp!B:B,disp!E:E))+0.25*(_xlfn.XLOOKUP(H12&$T$7,disp!A:A&disp!B:B,disp!E:E)+_xlfn.XLOOKUP(H12&$T$8,disp!A:A&disp!B:B,disp!E:E)+_xlfn.XLOOKUP(H12&$T$10,disp!A:A&disp!B:B,disp!E:E))} -> -22.426074 | N12: =ROUND(I12+J12+M12,0) -> -47 | O12: =ABS(_xlfn.FLOOR.MATH(N12,5)) -> 50 | P12: =LOOKUP(H12,Elementi!$H:$H,Elementi!$E:$E) -> 7 | T12: E2-Ritiro
C13: =_xlfn.XLOOKUP(H13,Nodi!$A:$A,Nodi!$B:$B) -> -289.865 | D13: =C13-$C$4 -> 65.318671 | G13: CS-09 | H13: 834 | I13: {=_xlfn.XLOOKUP(H13&$T$11,disp!A:A&disp!B:B,disp!E:E)} -> -11.4842 | J13: {=_xlfn.XLOOKUP(H13&$T$12,disp!A:A&disp!B:B,disp!E:E)} -> -4.733906 | K13: {=(MIN(INDEX(disp!$A$2:$H$274,MATCH(1,(disp!$A$2:$A$285=OUTput_Monta_TrSx!H13)*(disp!$B$2:$B$274="Tandem_Max(min)"),0),5),INDEX(disp!$A$2:$H$274,MATCH(1,(disp!$A$2:$A$285=OUTput_Monta_TrSx!H13)*(disp!$B$2:$B$274="tandem_Ecc(min)"),0),5)))} -> #N/A | L13: {=MIN(INDEX(disp!$A$2:$H$274,MATCH(1,(disp!$A$2:$A$285=OUTput_Monta_TrSx!H13)*(disp!$B$2:$B$274="Distr_Ecc(min)"),0),5),INDEX(disp!$A$2:$H$274,MATCH(1,(disp!$A$2:$A$285=OUTput_Monta_TrSx!H13)*(disp!$B$2:$B$274="Distr_Max(min)"),0),5))} -> #N/A | M13: {=0.25*(_xlfn.XLOOKUP(H13&$T$6,disp!A:A&disp!B:B,disp!E:E)+_xlfn.XLOOKUP(H13&$T$9,disp!A:A&disp!B:B,disp!E:E))+0.25*(_xlfn.XLOOKUP(H13&$T$7,disp!A:A&disp!B:B,disp!E:E)+_xlfn.XLOOKUP(H13&$T$8,disp!A:A&disp!B:B,disp!E:E)+_xlfn.XLOOKUP(H13&$T$10,disp!A:A&disp!B:B,disp!E:E))} -> -17.385714 | N13: =ROUND(I13+J13+M13,0) -> -34 | O13: =ABS(_xlfn.FLOOR.MATH(N13,5)) -> 35 | P13: =LOOKUP(H13,Elementi!$H:$H,Elementi!$E:$E) -> 8 | T13: 0
C14: =_xlfn.XLOOKUP(H14,Nodi!$A:$A,Nodi!$B:$B) -> -280.29435 | D14: =C14-$C$4 -> 74.889313 | E14: P02 | F14: CS-10 | H14: 821 | I14: {=_xlfn.XLOOKUP(H14&$T$11,disp!A:A&disp!B:B,disp!E:E)} -> -2.288966 | J14: {=_xlfn.XLOOKUP(H14&$T$12,disp!A:A&disp!B:B,disp!E:E)} -> -0.019632 | K14: {=(MIN(INDEX(disp!$A$2:$H$274,MATCH(1,(disp!$A$2:$A$285=OUTput_Monta_TrSx!H14)*(disp!$B$2:$B$274="Tandem_Max(min)"),0),5),INDEX(disp!$A$2:$H$274,MATCH(1,(disp!$A$2:$A$285=OUTput_Monta_TrSx!H14)*(disp!$B$2:$B$274="tandem_Ecc(min)"),0),5)))} -> #N/A | L14: {=MIN(INDEX(disp!$A$2:$H$274,MATCH(1,(disp!$A$2:$A$285=OUTput_Monta_TrSx!H14)*(disp!$B$2:$B$274="Distr_Ecc(min)"),0),5),INDEX(disp!$A$2:$H$274,MATCH(1,(disp!$A$2:$A$285=OUTput_Monta_TrSx!H14)*(disp!$B$2:$B$274="Distr_Max(min)"),0),5))} -> #N/A | M14: {=0.25*(_xlfn.XLOOKUP(H14&$T$6,disp!A:A&disp!B:B,disp!E:E)+_xlfn.XLOOKUP(H14&$T$9,disp!A:A&disp!B:B,disp!E:E))+0.25*(_xlfn.XLOOKUP(H14&$T$7,disp!A:A&disp!B:B,disp!E:E)+_xlfn.XLOOKUP(H14&$T$8,disp!A:A&disp!B:B,disp!E:E)+_xlfn.XLOOKUP(H14&$T$10,disp!A:A&disp!B:B,disp!E:E))} -> -5.3549582 | N14: =ROUND(I14+J14+M14,0) -> -8 | O14: 0 | P14: =LOOKUP(H14,Elementi!$H:$H,Elementi!$E:$E) -> 9
C15: =_xlfn.XLOOKUP(H15,Nodi!$A:$A,Nodi!$B:$B) -> -275.38218 | D15: =C15-$C$4 -> 79.801487 | H15: 814 | I15: {=_xlfn.XLOOKUP(H15&$T$11,disp!A:A&disp!B:B,disp!E:E)} -> 0 | J15: {=_xlfn.XLOOKUP(H15&$T$12,disp!A:A&disp!B:B,disp!E:E)} -> 0 | K15: {=(MIN(INDEX(disp!$A$2:$H$274,MATCH(1,(disp!$A$2:$A$285=OUTput_Monta_TrSx!H15)*(disp!$B$2:$B$274="Tandem_Max(min)"),0),5),INDEX(disp!$A$2:$H$274,MATCH(1,(disp!$A$2:$A$285=OUTput_Monta_TrSx!H15)*(disp!$B$2:$B$274="tandem_Ecc(min)"),0),5)))} -> #N/A | L15: {=MIN(INDEX(disp!$A$2:$H$274,MATCH(1,(disp!$A$2:$A$285=OUTput_Monta_TrSx!H15)*(disp!$B$2:$B$274="Distr_Ecc(min)"),0),5),INDEX(disp!$A$2:$H$274,MATCH(1,(disp!$A$2:$A$285=OUTput_Monta_TrSx!H15)*(disp!$B$2:$B$274="Distr_Max(min)"),0),5))} -> #N/A | M15: {=0.25*(_xlfn.XLOOKUP(H15&$T$6,disp!A:A&disp!B:B,disp!E:E)+_xlfn.XLOOKUP(H15&$T$9,disp!A:A&disp!B:B,disp!E:E))+0.25*(_xlfn.XLOOKUP(H15&$T$7,disp!A:A&disp!B:B,disp!E:E)+_xlfn.XLOOKUP(H15&$T$8,disp!A:A&disp!B:B,disp!E:E)+_xlfn.XLOOKUP(H15&$T$10,disp!A:A&disp!B:B,disp!E:E))} -> 0 | N15: =ROUND(I15+J15+M15,0) -> 0 | O15: =ABS(_xlfn.FLOOR.MATH(N15,5)) -> 0 | P15: =LOOKUP(H15,Elementi!$H:$H,Elementi!$E:$E) -> 10
C16: =_xlfn.XLOOKUP(H16,Nodi!$A:$A,Nodi!$B:$B) -> -270.4973 | D16: =C16-$C$4 -> 84.686364 | G16: CS-11 | H16: 807 | I16: {=_xlfn.XLOOKUP(H16&$T$11,disp!A:A&disp!B:B,disp!E:E)} -> -2.267648 | J16: {=_xlfn.XLOOKUP(H16&$T$12,disp!A:A&disp!B:B,disp!E:E)} -> -0.756836 | K16: {=(MIN(INDEX(disp!$A$2:$H$274,MATCH(1,(disp!$A$2:$A$285=OUTput_Monta_TrSx!H16)*(disp!$B$2:$B$274="Tandem_Max(min)"),0),5),INDEX(disp!$A$2:$H$274,MATCH(1,(disp!$A$2:$A$285=OUTput_Monta_TrSx!H16)*(disp!$B$2:$B$274="tandem_Ecc(min)"),0),5)))} -> #N/A | L16: {=MIN(INDEX(disp!$A$2:$H$274,MATCH(1,(disp!$A$2:$A$285=OUTput_Monta_TrSx!H16)*(disp!$B$2:$B$274="Distr_Ecc(min)"),0),5),INDEX(disp!$A$2:$H$274,MATCH(1,(disp!$A$2:$A$285=OUTput_Monta_TrSx!H16)*(disp!$B$2:$B$274="Distr_Max(min)"),0),5))} -> #N/A | M16: {=0.25*(_xlfn.XLOOKUP(H16&$T$6,disp!A:A&disp!B:B,disp!E:E)+_xlfn.XLOOKUP(H16&$T$9,disp!A:A&disp!B:B,disp!E:E))+0.25*(_xlfn.XLOOKUP(H16&$T$7,disp!A:A&disp!B:B,disp!E:E)+_xlfn.XLOOKUP(H16&$T$8,disp!A:A&disp!B:B,disp!E:E)+_xlfn.XLOOKUP(H16&$T$10,disp!A:A&disp!B:B,disp!E:E))} -> -5.833728 | N16: =ROUND(I16+J16+M16,0) -> -9 | O16: 0 | P16: =LOOKUP(H16,Elementi!$H:$H,Elementi!$E:$E) -> 10
C17: =_xlfn.XLOOKUP(H17,Nodi!$A:$A,Nodi!$B:$B) -> -260.48305 | D17: =C17-$C$4 -> 94.700616 | F17: CS-12 | H17: 794 | I17: {=_xlfn.XLOOKUP(H17&$T$11,disp!A:A&disp!B:B,disp!E:E)} -> -11.359612 | J17: {=_xlfn.XLOOKUP(H17&$T$12,disp!A:A&disp!B:B,disp!E:E)} -> -6.682896 | K17: {=(MIN(INDEX(disp!$A$2:$H$274,MATCH(1,(disp!$A$2:$A$285=OUTput_Monta_TrSx!H17)*(disp!$B$2:$B$274="Tandem_Max(min)"),0),5),INDEX(disp!$A$2:$H$274,MATCH(1,(disp!$A$2:$A$285=OUTput_Monta_TrSx!H17)*(disp!$B$2:$B$274="tandem_Ecc(min)"),0),5)))} -> #N/A | L17: {=MIN(INDEX(disp!$A$2:$H$274,MATCH(1,(disp!$A$2:$A$285=OUTput_Monta_TrSx!H17)*(disp!$B$2:$B$274="Distr_Ecc(min)"),0),5),INDEX(disp!$A$2:$H$274,MATCH(1,(disp!$A$2:$A$285=OUTput_Monta_TrSx!H17)*(disp!$B$2:$B$274="Distr_Max(min)"),0),5))} -> #N/A | M17: {=0.25*(_xlfn.XLOOKUP(H17&$T$6,disp!A:A&disp!B:B,disp!E:E)+_xlfn.XLOOKUP(H17&$T$9,disp!A:A&disp!B:B,disp!E:E))+0.25*(_xlfn.XLOOKUP(H17&$T$7,disp!A:A&disp!B:B,disp!E:E)+_xlfn.XLOOKUP(H17&$T$8,disp!A:A&disp!B:B,disp!E:E)+_xlfn.XLOOKUP(H17&$T$10,disp!A:A&disp!B:B,disp!E:E))} -> -19.151507 | N17: =ROUND(I17+J17+M17,0) -> -37 | O17: =ABS(_xlfn.FLOOR.MATH(N17,5)) -> 40 | P17: =LOOKUP(H17,Elementi!$H:$H,Elementi!$E:$E) -> 11
C18: =_xlfn.XLOOKUP(H18,Nodi!$A:$A,Nodi!$B:$B) -> -250.24802 | D18: =C18-$C$4 -> 104.93565 | G18: CS-12 | H18: 781 | I18: {=_xlfn.XLOOKUP(H18&$T$11,disp!A:A&disp!B:B,disp!E:E)} -> -15.973411 | J18: {=_xlfn.XLOOKUP(H18&$T$12,disp!A:A&disp!B:B,disp!E:E)} -> -11.322448 | K18: {=(MIN(INDEX(disp!$A$2:$H$274,MATCH(1,(disp!$A$2:$A$285=OUTput_Monta_TrSx!H18)*(disp!$B$2:$B$274="Tandem_Max(min)"),0),5),INDEX(disp!$A$2:$H$274,MATCH(1,(disp!$A$2:$A$285=OUTput_Monta_TrSx!H18)*(disp!$B$2:$B$274="tandem_Ecc(min)"),0),5)))} -> #N/A | L18: {=MIN(INDEX(disp!$A$2:$H$274,MATCH(1,(disp!$A$2:$A$285=OUTput_Monta_TrSx!H18)*(disp!$B$2:$B$274="Distr_Ecc(min)"),0),5),INDEX(disp!$A$2:$H$274,MATCH(1,(disp!$A$2:$A$285=OUTput_Monta_TrSx!H18)*(disp!$B$2:$B$274="Distr_Max(min)"),0),5))} -> #N/A | M18: {=0.25*(_xlfn.XLOOKUP(H18&$T$6,disp!A:A&disp!B:B,disp!E:E)+_xlfn.XLOOKUP(H18&$T$9,disp!A:A&disp!B:B,disp!E:E))+0.25*(_xlfn.XLOOKUP(H18&$T$7,disp!A:A&disp!B:B,disp!E:E)+_xlfn.XLOOKUP(H18&$T$8,disp!A:A&disp!B:B,disp!E:E)+_xlfn.XLOOKUP(H18&$T$10,disp!A:A&disp!B:B,disp!E:E))} -> -25.343604 | N18: =ROUND(I18+J18+M18,0) -> -53 | O18: =ABS(_xlfn.FLOOR.MATH(N18,5)) -> 55 | P18: =LOOKUP(H18,Elementi!$H:$H,Elementi!$E:$E) -> 12
C19: =_xlfn.XLOOKUP(H19,Nodi!$A:$A,Nodi!$B:$B) -> -239.84479 | D19: =C19-$C$4 -> 115.33887 | F19: CS-11 | H19: 768 | I19: {=_xlfn.XLOOKUP(H19&$T$11,disp!A:A&disp!B:B,disp!E:E)} -> -11.443136 | J19: {=_xlfn.XLOOKUP(H19&$T$12,disp!A:A&disp!B:B,disp!E:E)} -> -6.532497 | K19: {=(MIN(INDEX(disp!$A$2:$H$274,MATCH(1,(disp!$A$2:$A$285=OUTput_Monta_TrSx!H19)*(disp!$B$2:$B$274="Tandem_Max(min)"),0),5),INDEX(disp!$A$2:$H$274,MATCH(1,(disp!$A$2:$A$285=OUTput_Monta_TrSx!H19)*(disp!$B$2:$B$274="tandem_Ecc(min)"),0),5)))} -> #N/A | L19: {=MIN(INDEX(disp!$A$2:$H$274,MATCH(1,(disp!$A$2:$A$285=OUTput_Monta_TrSx!H19)*(disp!$B$2:$B$274="Distr_Ecc(min)"),0),5),INDEX(disp!$A$2:$H$274,MATCH(1,(disp!$A$2:$A$285=OUTput_Monta_TrSx!H19)*(disp!$B$2:$B$274="Distr_Max(min)"),0),5))} -> #N/A | M19: {=0.25*(_xlfn.XLOOKUP(H19&$T$6,disp!A:A&disp!B:B,disp!E:E)+_xlfn.XLOOKUP(H19&$T$9,disp!A:A&disp!B:B,disp!E:E))+0.25*(_xlfn.XLOOKUP(H19&$T$7,disp!A:A&disp!B:B,disp!E:E)+_xlfn.XLOOKUP(H19&$T$8,disp!A:A&disp!B:B,disp!E:E)+_xlfn.XLOOKUP(H19&$T$10,disp!A:A&disp!B:B,disp!E:E))} -> -19.159943 | N19: =ROUND(I19+J19+M19,0) -> -37 | O19: =ABS(_xlfn.FLOOR.MATH(N19,5)) -> 40 | P19: =LOOKUP(H19,Elementi!$H:$H,Elementi!$E:$E) -> 12
C20: =_xlfn.XLOOKUP(H20,Nodi!$A:$A,Nodi!$B:$B) -> -229.27229 | D20: =C20-$C$4 -> 125.91137 | E20: P03 | G20: CS-10 | H20: 755 | I20: {=_xlfn.XLOOKUP(H20&$T$11,disp!A:A&disp!B:B,disp!E:E)} -> -2.356774 | J20: {=_xlfn.XLOOKUP(H20&$T$12,disp!A:A&disp!B:B,disp!E:E)} -> -0.629924 | K20: {=(MIN(INDEX(disp!$A$2:$H$274,MATCH(1,(disp!$A$2:$A$285=OUTput_Monta_TrSx!H20)*(disp!$B$2:$B$274="Tandem_Max(min)"),0),5),INDEX(disp!$A$2:$H$274,MATCH(1,(disp!$A$2:$A$285=OUTput_Monta_TrSx!H20)*(disp!$B$2:$B$274="tandem_Ecc(min)"),0),5)))} -> #N/A | L20: {=MIN(INDEX(disp!$A$2:$H$274,MATCH(1,(disp!$A$2:$A$285=OUTput_Monta_TrSx!H20)*(disp!$B$2:$B$274="Distr_Ecc(min)"),0),5),INDEX(disp!$A$2:$H$274,MATCH(1,(disp!$A$2:$A$285=OUTput_Monta_TrSx!H20)*(disp!$B$2:$B$274="Distr_Max(min)"),0),5))} -> #N/A | M20: {=0.25*(_xlfn.XLOOKUP(H20&$T$6,disp!A:A&disp!B:B,disp!E:E)+_xlfn.XLOOKUP(H20&$T$9,disp!A:A&disp!B:B,disp!E:E))+0.25*(_xlfn.XLOOKUP(H20&$T$7,disp!A:A&disp!B:B,disp!E:E)+_xlfn.XLOOKUP(H20&$T$8,disp!A:A&disp!B:B,disp!E:E)+_xlfn.XLOOKUP(H20&$T$10,disp!A:A&disp!B:B,disp!E:E))} -> -5.8918983 | N20: =ROUND(I20+J20+M20,0) -> -9 | O20: 0 | P20: =LOOKUP(H20,Elementi!$H:$H,Elementi!$E:$E) -> 11
C21: =_xlfn.XLOOKUP(H21,Nodi!$A:$A,Nodi!$B:$B) -> -223.88602 | D21: =C21-$C$4 -> 131.29764 | H21: 749 | I21: {=_xlfn.XLOOKUP(H21&$T$11,disp!A:A&disp!B:B,disp!E:E)} -> 0 | J21: {=_xlfn.XLOOKUP(H21&$T$12,disp!A:A&disp!B:B,disp!E:E)} -> 0 | K21: {=(MIN(INDEX(disp!$A$2:$H$274,MATCH(1,(disp!$A$2:$A$285=OUTput_Monta_TrSx!H21)*(disp!$B$2:$B$274="Tandem_Max(min)"),0),5),INDEX(disp!$A$2:$H$274,MATCH(1,(disp!$A$2:$A$285=OUTput_Monta_TrSx!H21)*(disp!$B$2:$B$274="tandem_Ecc(min)"),0),5)))} -> #N/A | L21: {=MIN(INDEX(disp!$A$2:$H$274,MATCH(1,(disp!$A$2:$A$285=OUTput_Monta_TrSx!H21)*(disp!$B$2:$B$274="Distr_Ecc(min)"),0),5),INDEX(disp!$A$2:$H$274,MATCH(1,(disp!$A$2:$A$285=OUTput_Monta_TrSx!H21)*(disp!$B$2:$B$274="Distr_Max(min)"),0),5))} -> #N/A | M21: {=0.25*(_xlfn.XLOOKUP(H21&$T$6,disp!A:A&disp!B:B,disp!E:E)+_xlfn.XLOOKUP(H21&$T$9,disp!A:A&disp!B:B,disp!E:E))+0.25*(_xlfn.XLOOKUP(H21&$T$7,disp!A:A&disp!B:B,disp!E:E)+_xlfn.XLOOKUP(H21&$T$8,disp!A:A&disp!B:B,disp!E:E)+_xlfn.XLOOKUP(H21&$T$10,disp!A:A&disp!B:B,disp!E:E))} -> 0 | N21: =ROUND(I21+J21+M21,0) -> 0 | O21: =ABS(_xlfn.FLOOR.MATH(N21,5)) -> 0 | P21: =LOOKUP(H21,Elementi!$H:$H,Elementi!$E:$E) -> 10
C22: =_xlfn.XLOOKUP(H22,Nodi!$A:$A,Nodi!$B:$B) -> -218.53096 | D22: =C22-$C$4 -> 136.65271 | F22: CS-11 | H22: 742 | I22: {=_xlfn.XLOOKUP(H22&$T$11,disp!A:A&disp!B:B,disp!E:E)} -> -2.144777 | J22: {=_xlfn.XLOOKUP(H22&$T$12,disp!A:A&disp!B:B,disp!E:E)} -> -0.276881 | K22: {=(MIN(INDEX(disp!$A$2:$H$274,MATCH(1,(disp!$A$2:$A$285=OUTput_Monta_TrSx!H22)*(disp!$B$2:$B$274="Tandem_Max(min)"),0),5),INDEX(disp!$A$2:$H$274,MATCH(1,(disp!$A$2:$A$285=OUTput_Monta_TrSx!H22)*(disp!$B$2:$B$274="tandem_Ecc(min)"),0),5)))} -> #N/A | L22: {=MIN(INDEX(disp!$A$2:$H$274,MATCH(1,(disp!$A$2:$A$285=OUTput_Monta_TrSx!H22)*(disp!$B$2:$B$274="Distr_Ecc(min)"),0),5),INDEX(disp!$A$2:$H$274,MATCH(1,(disp!$A$2:$A$285=OUTput_Monta_TrSx!H22)*(disp!$B$2:$B$274="Distr_Max(min)"),0),5))} -> #N/A | M22: {=0.25*(_xlfn.XLOOKUP(H22&$T$6,disp!A:A&disp!B:B,disp!E:E)+_xlfn.XLOOKUP(H22&$T$9,disp!A:A&disp!B:B,disp!E:E))+0.25*(_xlfn.XLOOKUP(H22&$T$7,disp!A:A&disp!B:B,disp!E:E)+_xlfn.XLOOKUP(H22&$T$8,disp!A:A&disp!B:B,disp!E:E)+_xlfn.XLOOKUP(H22&$T$10,disp!A:A&disp!B:B,disp!E:E))} -> -5.5126748 | N22: =ROUND(I22+J22+M22,0) -> -8 | O22: 0 | P22: =LOOKUP(H22,Elementi!$H:$H,Elementi!$E:$E) -> 10
C23: =_xlfn.XLOOKUP(H23,Nodi!$A:$A,Nodi!$B:$B) -> -207.59037 | D23: =C23-$C$4 -> 147.5933 | G23: CS-12 | H23: 729 | I23: {=_xlfn.XLOOKUP(H23&$T$11,disp!A:A&disp!B:B,disp!E:E)} -> -10.9469 | J23: {=_xlfn.XLOOKUP(H23&$T$12,disp!A:A&disp!B:B,disp!E:E)} -> -5.651898 | K23: {=(MIN(INDEX(disp!$A$2:$H$274,MATCH(1,(disp!$A$2:$A$285=OUTput_Monta_TrSx!H23)*(disp!$B$2:$B$274="Tandem_Max(min)"),0),5),INDEX(disp!$A$2:$H$274,MATCH(1,(disp!$A$2:$A$285=OUTput_Monta_TrSx!H23)*(disp!$B$2:$B$274="tandem_Ecc(min)"),0),5)))} -> #N/A | L23: {=MIN(INDEX(disp!$A$2:$H$274,MATCH(1,(disp!$A$2:$A$285=OUTput_Monta_TrSx!H23)*(disp!$B$2:$B$274="Distr_Ecc(min)"),0),5),INDEX(disp!$A$2:$H$274,MATCH(1,(disp!$A$2:$A$285=OUTput_Monta_TrSx!H23)*(disp!$B$2:$B$274="Distr_Max(min)"),0),5))} -> #N/A | M23: {=0.25*(_xlfn.XLOOKUP(H23&$T$6,disp!A:A&disp!B:B,disp!E:E)+_xlfn.XLOOKUP(H23&$T$9,disp!A:A&disp!B:B,disp!E:E))+0.25*(_xlfn.XLOOKUP(H23&$T$7,disp!A:A&disp!B:B,disp!E:E)+_xlfn.XLOOKUP(H23&$T$8,disp!A:A&disp!B:B,disp!E:E)+_xlfn.XLOOKUP(H23&$T$10,disp!A:A&disp!B:B,disp!E:E))} -> -18.301625 | N23: =ROUND(I23+J23+M23,0) -> -35 | O23: =ABS(_xlfn.FLOOR.MATH(N23,5)) -> 35 | P23: =LOOKUP(H23,Elementi!$H:$H,Elementi!$E:$E) -> 11
C24: =_xlfn.XLOOKUP(H24,Nodi!$A:$A,Nodi!$B:$B) -> -196.50667 | D24: =C24-$C$4 -> 158.677 | F24: CS-12 | H24: 716 | I24: {=_xlfn.XLOOKUP(H24&$T$11,disp!A:A&disp!B:B,disp!E:E)} -> -15.296766 | J24: {=_xlfn.XLOOKUP(H24&$T$12,disp!A:A&disp!B:B,disp!E:E)} -> -10.190999 | K24: {=(MIN(INDEX(disp!$A$2:$H$274,MATCH(1,(disp!$A$2:$A$285=OUTput_Monta_TrSx!H24)*(disp!$B$2:$B$274="Tandem_Max(min)"),0),5),INDEX(disp!$A$2:$H$274,MATCH(1,(disp!$A$2:$A$285=OUTput_Monta_TrSx!H24)*(disp!$B$2:$B$274="tandem_Ecc(min)"),0),5)))} -> #N/A | L24: {=MIN(INDEX(disp!$A$2:$H$274,MATCH(1,(disp!$A$2:$A$285=OUTput_Monta_TrSx!H24)*(disp!$B$2:$B$274="Distr_Ecc(min)"),0),5),INDEX(disp!$A$2:$H$274,MATCH(1,(disp!$A$2:$A$285=OUTput_Monta_TrSx!H24)*(disp!$B$2:$B$274="Distr_Max(min)"),0),5))} -> #N/A | M24: {=0.25*(_xlfn.XLOOKUP(H24&$T$6,disp!A:A&disp!B:B,disp!E:E)+_xlfn.XLOOKUP(H24&$T$9,disp!A:A&disp!B:B,disp!E:E))+0.25*(_xlfn.XLOOKUP(H24&$T$7,disp!A:A&disp!B:B,disp!E:E)+_xlfn.XLOOKUP(H24&$T$8,disp!A:A&disp!B:B,disp!E:E)+_xlfn.XLOOKUP(H24&$T$10,disp!A:A&disp!B:B,disp!E:E))} -> -24.242961 | N24: =ROUND(I24+J24+M24,0) -> -50 | O24: =ABS(_xlfn.FLOOR.MATH(N24,5)) -> 50 | P24: =LOOKUP(H24,Elementi!$H:$H,Elementi!$E:$E) -> 12
C25: =_xlfn.XLOOKUP(H25,Nodi!$A:$A,Nodi!$B:$B) -> -185.29453 | D25: =C25-$C$4 -> 169.88914 | G25: CS-11 | H25: 703 | I25: {=_xlfn.XLOOKUP(H25&$T$11,disp!A:A&disp!B:B,disp!E:E)} -> -10.688236 | J25: {=_xlfn.XLOOKUP(H25&$T$12,disp!A:A&disp!B:B,disp!E:E)} -> -5.714604 | K25: {=(MIN(INDEX(disp!$A$2:$H$274,MATCH(1,(disp!$A$2:$A$285=OUTput_Monta_TrSx!H25)*(disp!$B$2:$B$274="Tandem_Max(min)"),0),5),INDEX(disp!$A$2:$H$274,MATCH(1,(disp!$A$2:$A$285=OUTput_Monta_TrSx!H25)*(disp!$B$2:$B$274="tandem_Ecc(min)"),0),5)))} -> #N/A | L25: {=MIN(INDEX(disp!$A$2:$H$274,MATCH(1,(disp!$A$2:$A$285=OUTput_Monta_TrSx!H25)*(disp!$B$2:$B$274="Distr_Ecc(min)"),0),5),INDEX(disp!$A$2:$H$274,MATCH(1,(disp!$A$2:$A$285=OUTput_Monta_TrSx!H25)*(disp!$B$2:$B$274="Distr_Max(min)"),0),5))} -> #N/A | M25: {=0.25*(_xlfn.XLOOKUP(H25&$T$6,disp!A:A&disp!B:B,disp!E:E)+_xlfn.XLOOKUP(H25&$T$9,disp!A:A&disp!B:B,disp!E:E))+0.25*(_xlfn.XLOOKUP(H25&$T$7,disp!A:A&disp!B:B,disp!E:E)+_xlfn.XLOOKUP(H25&$T$8,disp!A:A&disp!B:B,disp!E:E)+_xlfn.XLOOKUP(H25&$T$10,disp!A:A&disp!B:B,disp!E:E))} -> -18.194314 | N25: =ROUND(I25+J25+M25,0) -> -35 | O25: =ABS(_xlfn.FLOOR.MATH(N25,5)) -> 35 | P25: =LOOKUP(H25,Elementi!$H:$H,Elementi!$E:$E) -> 12
C26: =_xlfn.XLOOKUP(H26,Nodi!$A:$A,Nodi!$B:$B) -> -173.92095 | D26: =C26-$C$4 -> 181.26272 | E26: P04 | F26: CS-10 | H26: 690 | I26: {=_xlfn.XLOOKUP(H26&$T$11,disp!A:A&disp!B:B,disp!E:E)} -> -1.927735 | J26: {=_xlfn.XLOOKUP(H26&$T$12,disp!A:A&disp!B:B,disp!E:E)} -> -0.327915 | K26: {=(MIN(INDEX(disp!$A$2:$H$274,MATCH(1,(disp!$A$2:$A$285=OUTput_Monta_TrSx!H26)*(disp!$B$2:$B$274="Tandem_Max(min)"),0),5),INDEX(disp!$A$2:$H$274,MATCH(1,(disp!$A$2:$A$285=OUTput_Monta_TrSx!H26)*(disp!$B$2:$B$274="tandem_Ecc(min)"),0),5)))} -> #N/A | L26: {=MIN(INDEX(disp!$A$2:$H$274,MATCH(1,(disp!$A$2:$A$285=OUTput_Monta_TrSx!H26)*(disp!$B$2:$B$274="Distr_Ecc(min)"),0),5),INDEX(disp!$A$2:$H$274,MATCH(1,(disp!$A$2:$A$285=OUTput_Monta_TrSx!H26)*(disp!$B$2:$B$274="Distr_Max(min)"),0),5))} -> #N/A | M26: {=0.25*(_xlfn.XLOOKUP(H26&$T$6,disp!A:A&disp!B:B,disp!E:E)+_xlfn.XLOOKUP(H26&$T$9,disp!A:A&disp!B:B,disp!E:E))+0.25*(_xlfn.XLOOKUP(H26&$T$7,disp!A:A&disp!B:B,disp!E:E)+_xlfn.XLOOKUP(H26&$T$8,disp!A:A&disp!B:B,disp!E:E)+_xlfn.XLOOKUP(H26&$T$10,disp!A:A&disp!B:B,disp!E:E))} -> -5.435699 | N26: =ROUND(I26+J26+M26,0) -> -8 | O26: 0 | P26: =LOOKUP(H26,Elementi!$H:$H,Elementi!$E:$E) -> 11
C27: =_xlfn.XLOOKUP(H27,Nodi!$A:$A,Nodi!$B:$B) -> -168.204 | D27: =C27-$C$4 -> 186.97967 | H27: 684 | I27: {=_xlfn.XLOOKUP(H27&$T$11,disp!A:A&disp!B:B,disp!E:E)} -> 0 | J27: {=_xlfn.XLOOKUP(H27&$T$12,disp!A:A&disp!B:B,disp!E:E)} -> 0 | K27: {=(MIN(INDEX(disp!$A$2:$H$274,MATCH(1,(disp!$A$2:$A$285=OUTput_Monta_TrSx!H27)*(disp!$B$2:$B$274="Tandem_Max(min)"),0),5),INDEX(disp!$A$2:$H$274,MATCH(1,(disp!$A$2:$A$285=OUTput_Monta_TrSx!H27)*(disp!$B$2:$B$274="tandem_Ecc(min)"),0),5)))} -> #N/A | L27: {=MIN(INDEX(disp!$A$2:$H$274,MATCH(1,(disp!$A$2:$A$285=OUTput_Monta_TrSx!H27)*(disp!$B$2:$B$274="Distr_Ecc(min)"),0),5),INDEX(disp!$A$2:$H$274,MATCH(1,(disp!$A$2:$A$285=OUTput_Monta_TrSx!H27)*(disp!$B$2:$B$274="Distr_Max(min)"),0),5))} -> #N/A | M27: {=0.25*(_xlfn.XLOOKUP(H27&$T$6,disp!A:A&disp!B:B,disp!E:E)+_xlfn.XLOOKUP(H27&$T$9,disp!A:A&disp!B:B,disp!E:E))+0.25*(_xlfn.XLOOKUP(H27&$T$7,disp!A:A&disp!B:B,disp!E:E)+_xlfn.XLOOKUP(H27&$T$8,disp!A:A&disp!B:B,disp!E:E)+_xlfn.XLOOKUP(H27&$T$10,disp!A:A&disp!B:B,disp!E:E))} -> 0 | N27: =ROUND(I27+J27+M27,0) -> 0 | O27: =ABS(_xlfn.FLOOR.MATH(N27,5)) -> 0 | P27: =LOOKUP(H27,Elementi!$H:$H,Elementi!$E:$E) -> 10
C28: =_xlfn.XLOOKUP(H28,Nodi!$A:$A,Nodi!$B:$B) -> -162.45639 | D28: =C28-$C$4 -> 192.72728 | G28: CS-11 | H28: 677 | I28: {=_xlfn.XLOOKUP(H28&$T$11,disp!A:A&disp!B:B,disp!E:E)} -> -2.729537 | J28: {=_xlfn.XLOOKUP(H28&$T$12,disp!A:A&disp!B:B,disp!E:E)} -> -0.54676 | K28: {=(MIN(INDEX(disp!$A$2:$H$274,MATCH(1,(disp!$A$2:$A$285=OUTput_Monta_TrSx!H28)*(disp!$B$2:$B$274="Tandem_Max(min)"),0),5),INDEX(disp!$A$2:$H$274,MATCH(1,(disp!$A$2:$A$285=OUTput_Monta_TrSx!H28)*(disp!$B$2:$B$274="tandem_Ecc(min)"),0),5)))} -> #N/A | L28: {=MIN(INDEX(disp!$A$2:$H$274,MATCH(1,(disp!$A$2:$A$285=OUTput_Monta_TrSx!H28)*(disp!$B$2:$B$274="Distr_Ecc(min)"),0),5),INDEX(disp!$A$2:$H$274,MATCH(1,(disp!$A$2:$A$285=OUTput_Monta_TrSx!H28)*(disp!$B$2:$B$274="Distr_Max(min)"),0),5))} -> #N/A | M28: {=0.25*(_xlfn.XLOOKUP(H28&$T$6,disp!A:A&disp!B:B,disp!E:E)+_xlfn.XLOOKUP(H28&$T$9,disp!A:A&disp!B:B,disp!E:E))+0.25*(_xlfn.XLOOKUP(H28&$T$7,disp!A:A&disp!B:B,disp!E:E)+_xlfn.XLOOKUP(H28&$T$8,disp!A:A&disp!B:B,disp!E:E)+_xlfn.XLOOKUP(H28&$T$10,disp!A:A&disp!B:B,disp!E:E))} -> -5.9224405 | N28: =ROUND(I28+J28+M28,0) -> -9 | O28: 0 | P28: =LOOKUP(H28,Elementi!$H:$H,Elementi!$E:$E) -> 10
C29: =_xlfn.XLOOKUP(H29,Nodi!$A:$A,Nodi!$B:$B) -> -150.85464 | D29: =C29-$C$4 -> 204.32903 | F29: CS-12 | H29: 664 | I29: {=_xlfn.XLOOKUP(H29&$T$11,disp!A:A&disp!B:B,disp!E:E)} -> -12.735097 | J29: {=_xlfn.XLOOKUP(H29&$T$12,disp!A:A&disp!B:B,disp!E:E)} -> -6.233163 | K29: {=(MIN(INDEX(disp!$A$2:$H$274,MATCH(1,(disp!$A$2:$A$285=OUTput_Monta_TrSx!H29)*(disp!$B$2:$B$274="Tandem_Max(min)"),0),5),INDEX(disp!$A$2:$H$274,MATCH(1,(disp!$A$2:$A$285=OUTput_Monta_TrSx!H29)*(disp!$B$2:$B$274="tandem_Ecc(min)"),0),5)))} -> #N/A | L29: {=MIN(INDEX(disp!$A$2:$H$274,MATCH(1,(disp!$A$2:$A$285=OUTput_Monta_TrSx!H29)*(disp!$B$2:$B$274="Distr_Ecc(min)"),0),5),INDEX(disp!$A$2:$H$274,MATCH(1,(disp!$A$2:$A$285=OUTput_Monta_TrSx!H29)*(disp!$B$2:$B$274="Distr_Max(min)"),0),5))} -> #N/A | M29: {=0.25*(_xlfn.XLOOKUP(H29&$T$6,disp!A:A&disp!B:B,disp!E:E)+_xlfn.XLOOKUP(H29&$T$9,disp!A:A&disp!B:B,disp!E:E))+0.25*(_xlfn.XLOOKUP(H29&$T$7,disp!A:A&disp!B:B,disp!E:E)+_xlfn.XLOOKUP(H29&$T$8,disp!A:A&disp!B:B,disp!E:E)+_xlfn.XLOOKUP(H29&$T$10,disp!A:A&disp!B:B,disp!E:E))} -> -19.340121 | N29: =ROUND(I29+J29+M29,0) -> -38 | O29: =ABS(_xlfn.FLOOR.MATH(N29,5)) -> 40 | P29: =LOOKUP(H29,Elementi!$H:$H,Elementi!$E:$E) -> 11
C30: =_xlfn.XLOOKUP(H30,Nodi!$A:$A,Nodi!$B:$B) -> -139.15078 | D30: =C30-$C$4 -> 216.03289 | G30: CS-12 | H30: 651 | I30: {=_xlfn.XLOOKUP(H30&$T$11,disp!A:A&disp!B:B,disp!E:E)} -> -17.825518 | J30: {=_xlfn.XLOOKUP(H30&$T$12,disp!A:A&disp!B:B,disp!E:E)} -> -10.906815 | K30: {=(MIN(INDEX(disp!$A$2:$H$274,MATCH(1,(disp!$A$2:$A$285=OUTput_Monta_TrSx!H30)*(disp!$B$2:$B$274="Tandem_Max(min)"),0),5),INDEX(disp!$A$2:$H$274,MATCH(1,(disp!$A$2:$A$285=OUTput_Monta_TrSx!H30)*(disp!$B$2:$B$274="tandem_Ecc(min)"),0),5)))} -> #N/A | L30: {=MIN(INDEX(disp!$A$2:$H$274,MATCH(1,(disp!$A$2:$A$285=OUTput_Monta_TrSx!H30)*(disp!$B$2:$B$274="Distr_Ecc(min)"),0),5),INDEX(disp!$A$2:$H$274,MATCH(1,(disp!$A$2:$A$285=OUTput_Monta_TrSx!H30)*(disp!$B$2:$B$274="Distr_Max(min)"),0),5))} -> #N/A | M30: {=0.25*(_xlfn.XLOOKUP(H30&$T$6,disp!A:A&disp!B:B,disp!E:E)+_xlfn.XLOOKUP(H30&$T$9,disp!A:A&disp!B:B,disp!E:E))+0.25*(_xlfn.XLOOKUP(H30&$T$7,disp!A:A&disp!B:B,disp!E:E)+_xlfn.XLOOKUP(H30&$T$8,disp!A:A&disp!B:B,disp!E:E)+_xlfn.XLOOKUP(H30&$T$10,disp!A:A&disp!B:B,disp!E:E))} -> -25.514174 | N30: =ROUND(I30+J30+M30,0) -> -54 | O30: =ABS(_xlfn.FLOOR.MATH(N30,5)) -> 55 | P30: =LOOKUP(H30,Elementi!$H:$H,Elementi!$E:$E) -> 12
C31: =_xlfn.XLOOKUP(H31,Nodi!$A:$A,Nodi!$B:$B) -> -127.37714 | D31: =C31-$C$4 -> 227.80652 | F31: CS-15 | H31: 638 | I31: {=_xlfn.XLOOKUP(H31&$T$11,disp!A:A&disp!B:B,disp!E:E)} -> -12.842718 | J31: {=_xlfn.XLOOKUP(H31&$T$12,disp!A:A&disp!B:B,disp!E:E)} -> -6.513602 | K31: {=(MIN(INDEX(disp!$A$2:$H$274,MATCH(1,(disp!$A$2:$A$285=OUTput_Monta_TrSx!H31)*(disp!$B$2:$B$274="Tandem_Max(min)"),0),5),INDEX(disp!$A$2:$H$274,MATCH(1,(disp!$A$2:$A$285=OUTput_Monta_TrSx!H31)*(disp!$B$2:$B$274="tandem_Ecc(min)"),0),5)))} -> #N/A | L31: {=MIN(INDEX(disp!$A$2:$H$274,MATCH(1,(disp!$A$2:$A$285=OUTput_Monta_TrSx!H31)*(disp!$B$2:$B$274="Distr_Ecc(min)"),0),5),INDEX(disp!$A$2:$H$274,MATCH(1,(disp!$A$2:$A$285=OUTput_Monta_TrSx!H31)*(disp!$B$2:$B$274="Distr_Max(min)"),0),5))} -> #N/A | M31: {=0.25*(_xlfn.XLOOKUP(H31&$T$6,disp!A:A&disp!B:B,disp!E:E)+_xlfn.XLOOKUP(H31&$T$9,disp!A:A&disp!B:B,disp!E:E))+0.25*(_xlfn.XLOOKUP(H31&$T$7,disp!A:A&disp!B:B,disp!E:E)+_xlfn.XLOOKUP(H31&$T$8,disp!A:A&disp!B:B,disp!E:E)+_xlfn.XLOOKUP(H31&$T$10,disp!A:A&disp!B:B,disp!E:E))} -> -18.9768 | N31: =ROUND(I31+J31+M31,0) -> -38 | O31: =ABS(_xlfn.FLOOR.MATH(N31,5)) -> 40 | P31: =LOOKUP(H31,Elementi!$H:$H,Elementi!$E:$E) -> 12
C32: =_xlfn.XLOOKUP(H32,Nodi!$A:$A,Nodi!$B:$B) -> -115.52016 | D32: =C32-$C$4 -> 239.66351 | E32: P05 | G32: CS-14 | H32: 625 | I32: {=_xlfn.XLOOKUP(H32&$T$11,disp!A:A&disp!B:B,disp!E:E)} -> -2.663989 | J32: {=_xlfn.XLOOKUP(H32&$T$12,disp!A:A&disp!B:B,disp!E:E)} -> -0.774574 | K32: {=(MIN(INDEX(disp!$A$2:$H$274,MATCH(1,(disp!$A$2:$A$285=OUTput_Monta_TrSx!H32)*(disp!$B$2:$B$274="Tandem_Max(min)"),0),5),INDEX(disp!$A$2:$H$274,MATCH(1,(disp!$A$2:$A$285=OUTput_Monta_TrSx!H32)*(disp!$B$2:$B$274="tandem_Ecc(min)"),0),5)))} -> #N/A | L32: {=MIN(INDEX(disp!$A$2:$H$274,MATCH(1,(disp!$A$2:$A$285=OUTput_Monta_TrSx!H32)*(disp!$B$2:$B$274="Distr_Ecc(min)"),0),5),INDEX(disp!$A$2:$H$274,MATCH(1,(disp!$A$2:$A$285=OUTput_Monta_TrSx!H32)*(disp!$B$2:$B$274="Distr_Max(min)"),0),5))} -> #N/A | M32: {=0.25*(_xlfn.XLOOKUP(H32&$T$6,disp!A:A&disp!B:B,disp!E:E)+_xlfn.XLOOKUP(H32&$T$9,disp!A:A&disp!B:B,disp!E:E))+0.25*(_xlfn.XLOOKUP(H32&$T$7,disp!A:A&disp!B:B,disp!E:E)+_xlfn.XLOOKUP(H32&$T$8,disp!A:A&disp!B:B,disp!E:E)+_xlfn.XLOOKUP(H32&$T$10,disp!A:A&disp!B:B,disp!E:E))} -> -5.6698182 | N32: =ROUND(I32+J32+M32,0) -> -9 | O32: 0 | P32: =LOOKUP(H32,Elementi!$H:$H,Elementi!$E:$E) -> 15
C33: =_xlfn.XLOOKUP(H33,Nodi!$A:$A,Nodi!$B:$B) -> -109.54736 | D33: =C33-$C$4 -> 245.63631 | H33: 619 | I33: {=_xlfn.XLOOKUP(H33&$T$11,disp!A:A&disp!B:B,disp!E:E)} -> 0 | J33: {=_xlfn.XLOOKUP(H33&$T$12,disp!A:A&disp!B:B,disp!E:E)} -> 0 | K33: {=(MIN(INDEX(disp!$A$2:$H$274,MATCH(1,(disp!$A$2:$A$285=OUTput_Monta_TrSx!H33)*(disp!$B$2:$B$274="Tandem_Max(min)"),0),5),INDEX(disp!$A$2:$H$274,MATCH(1,(disp!$A$2:$A$285=OUTput_Monta_TrSx!H33)*(disp!$B$2:$B$274="tandem_Ecc(min)"),0),5)))} -> #N/A | L33: {=MIN(INDEX(disp!$A$2:$H$274,MATCH(1,(disp!$A$2:$A$285=OUTput_Monta_TrSx!H33)*(disp!$B$2:$B$274="Distr_Ecc(min)"),0),5),INDEX(disp!$A$2:$H$274,MATCH(1,(disp!$A$2:$A$285=OUTput_Monta_TrSx!H33)*(disp!$B$2:$B$274="Distr_Max(min)"),0),5))} -> #N/A | M33: {=0.25*(_xlfn.XLOOKUP(H33&$T$6,disp!A:A&disp!B:B,disp!E:E)+_xlfn.XLOOKUP(H33&$T$9,disp!A:A&disp!B:B,disp!E:E))+0.25*(_xlfn.XLOOKUP(H33&$T$7,disp!A:A&disp!B:B,disp!E:E)+_xlfn.XLOOKUP(H33&$T$8,disp!A:A&disp!B:B,disp!E:E)+_xlfn.XLOOKUP(H33&$T$10,disp!A:A&disp!B:B,disp!E:E))} -> 0 | N33: =ROUND(I33+J33+M33,0) -> 0 | O33: =ABS(_xlfn.FLOOR.MATH(N33,5)) -> 0 | P33: =LOOKUP(H33,Elementi!$H:$H,Elementi!$E:$E) -> 14
C34: =_xlfn.XLOOKUP(H34,Nodi!$A:$A,Nodi!$B:$B) -> -103.57728 | D34: =C34-$C$4 -> 251.60639 | F34: CS-13 | H34: 612 | I34: {=_xlfn.XLOOKUP(H34&$T$11,disp!A:A&disp!B:B,disp!E:E)} -> -2.671031 | J34: {=_xlfn.XLOOKUP(H34&$T$12,disp!A:A&disp!B:B,disp!E:E)} -> 0.013093 | K34: {=(MIN(INDEX(disp!$A$2:$H$274,MATCH(1,(disp!$A$2:$A$285=OUTput_Monta_TrSx!H34)*(disp!$B$2:$B$274="Tandem_Max(min)"),0),5),INDEX(disp!$A$2:$H$274,MATCH(1,(disp!$A$2:$A$285=OUTput_Monta_TrSx!H34)*(disp!$B$2:$B$274="tandem_Ecc(min)"),0),5)))} -> #N/A | L34: {=MIN(INDEX(disp!$A$2:$H$274,MATCH(1,(disp!$A$2:$A$285=OUTput_Monta_TrSx!H34)*(disp!$B$2:$B$274="Distr_Ecc(min)"),0),5),INDEX(disp!$A$2:$H$274,MATCH(1,(disp!$A$2:$A$285=OUTput_Monta_TrSx!H34)*(disp!$B$2:$B$274="Distr_Max(min)"),0),5))} -> #N/A | M34: {=0.25*(_xlfn.XLOOKUP(H34&$T$6,disp!A:A&disp!B:B,disp!E:E)+_xlfn.XLOOKUP(H34&$T$9,disp!A:A&disp!B:B,disp!E:E))+0.25*(_xlfn.XLOOKUP(H34&$T$7,disp!A:A&disp!B:B,disp!E:E)+_xlfn.XLOOKUP(H34&$T$8,disp!A:A&disp!B:B,disp!E:E)+_xlfn.XLOOKUP(H34&$T$10,disp!A:A&disp!B:B,disp!E:E))} -> -5.2170463 | N34: =ROUND(I34+J34+M34,0) -> -8 | O34: 0 | P34: =LOOKUP(H34,Elementi!$H:$H,Elementi!$E:$E) -> 14
C35: =_xlfn.XLOOKUP(H35,Nodi!$A:$A,Nodi!$B:$B) -> -91.557924 | D35: =C35-$C$4 -> 263.62574 | G35: CS-08 | H35: 599 | I35: {=_xlfn.XLOOKUP(H35&$T$11,disp!A:A&disp!B:B,disp!E:E)} -> -13.054099 | J35: {=_xlfn.XLOOKUP(H35&$T$12,disp!A:A&disp!B:B,disp!E:E)} -> -4.376355 | K35: {=(MIN(INDEX(disp!$A$2:$H$274,MATCH(1,(disp!$A$2:$A$285=OUTput_Monta_TrSx!H35)*(disp!$B$2:$B$274="Tandem_Max(min)"),0),5),INDEX(disp!$A$2:$H$274,MATCH(1,(disp!$A$2:$A$285=OUTput_Monta_TrSx!H35)*(disp!$B$2:$B$274="tandem_Ecc(min)"),0),5)))} -> #N/A | L35: {=MIN(INDEX(disp!$A$2:$H$274,MATCH(1,(disp!$A$2:$A$285=OUTput_Monta_TrSx!H35)*(disp!$B$2:$B$274="Distr_Ecc(min)"),0),5),INDEX(disp!$A$2:$H$274,MATCH(1,(disp!$A$2:$A$285=OUTput_Monta_TrSx!H35)*(disp!$B$2:$B$274="Distr_Max(min)"),0),5))} -> #N/A | M35: {=0.25*(_xlfn.XLOOKUP(H35&$T$6,disp!A:A&disp!B:B,disp!E:E)+_xlfn.XLOOKUP(H35&$T$9,disp!A:A&disp!B:B,disp!E:E))+0.25*(_xlfn.XLOOKUP(H35&$T$7,disp!A:A&disp!B:B,disp!E:E)+_xlfn.XLOOKUP(H35&$T$8,disp!A:A&disp!B:B,disp!E:E)+_xlfn.XLOOKUP(H35&$T$10,disp!A:A&disp!B:B,disp!E:E))} -> -17.624021 | N35: =ROUND(I35+J35+M35,0) -> -35 | O35: =ABS(_xlfn.FLOOR.MATH(N35,5)) -> 35 | P35: =LOOKUP(H35,Elementi!$H:$H,Elementi!$E:$E) -> 13
C36: =_xlfn.XLOOKUP(H36,Nodi!$A:$A,Nodi!$B:$B) -> -79.522561 | D36: =C36-$C$4 -> 275.66111 | F36: CS-07 | H36: 586 | I36: {=_xlfn.XLOOKUP(H36&$T$11,disp!A:A&disp!B:B,disp!E:E)} -> -18.225464 | J36: {=_xlfn.XLOOKUP(H36&$T$12,disp!A:A&disp!B:B,disp!E:E)} -> -7.975976 | K36: {=(MIN(INDEX(disp!$A$2:$H$274,MATCH(1,(disp!$A$2:$A$285=OUTput_Monta_TrSx!H36)*(disp!$B$2:$B$274="Tandem_Max(min)"),0),5),INDEX(disp!$A$2:$H$274,MATCH(1,(disp!$A$2:$A$285=OUTput_Monta_TrSx!H36)*(disp!$B$2:$B$274="tandem_Ecc(min)"),0),5)))} -> #N/A | L36: {=MIN(INDEX(disp!$A$2:$H$274,MATCH(1,(disp!$A$2:$A$285=OUTput_Monta_TrSx!H36)*(disp!$B$2:$B$274="Distr_Ecc(min)"),0),5),INDEX(disp!$A$2:$H$274,MATCH(1,(disp!$A$2:$A$285=OUTput_Monta_TrSx!H36)*(disp!$B$2:$B$274="Distr_Max(min)"),0),5))} -> #N/A | M36: {=0.25*(_xlfn.XLOOKUP(H36&$T$6,disp!A:A&disp!B:B,disp!E:E)+_xlfn.XLOOKUP(H36&$T$9,disp!A:A&disp!B:B,disp!E:E))+0.25*(_xlfn.XLOOKUP(H36&$T$7,disp!A:A&disp!B:B,disp!E:E)+_xlfn.XLOOKUP(H36&$T$8,disp!A:A&disp!B:B,disp!E:E)+_xlfn.XLOOKUP(H36&$T$10,disp!A:A&disp!B:B,disp!E:E))} -> -23.397596 | N36: =ROUND(I36+J36+M36,0) -> -50 | O36: =ABS(_xlfn.FLOOR.MATH(N36,5)) -> 50 | P36: =LOOKUP(H36,Elementi!$H:$H,Elementi!$E:$E) -> 8
C37: =_xlfn.XLOOKUP(H37,Nodi!$A:$A,Nodi!$B:$B) -> -67.442263 | D37: =C37-$C$4 -> 287.7414 | G37: CS-06 | H37: 573 | I37: {=_xlfn.XLOOKUP(H37&$T$11,disp!A:A&disp!B:B,disp!E:E)} -> -13.32161 | J37: {=_xlfn.XLOOKUP(H37&$T$12,disp!A:A&disp!B:B,disp!E:E)} -> -3.305837 | K37: {=(MIN(INDEX(disp!$A$2:$H$274,MATCH(1,(disp!$A$2:$A$285=OUTput_Monta_TrSx!H37)*(disp!$B$2:$B$274="Tandem_Max(min)"),0),5),INDEX(disp!$A$2:$H$274,MATCH(1,(disp!$A$2:$A$285=OUTput_Monta_TrSx!H37)*(disp!$B$2:$B$274="tandem_Ecc(min)"),0),5)))} -> #N/A | L37: {=MIN(INDEX(disp!$A$2:$H$274,MATCH(1,(disp!$A$2:$A$285=OUTput_Monta_TrSx!H37)*(disp!$B$2:$B$274="Distr_Ecc(min)"),0),5),INDEX(disp!$A$2:$H$274,MATCH(1,(disp!$A$2:$A$285=OUTput_Monta_TrSx!H37)*(disp!$B$2:$B$274="Distr_Max(min)"),0),5))} -> #N/A | M37: {=0.25*(_xlfn.XLOOKUP(H37&$T$6,disp!A:A&disp!B:B,disp!E:E)+_xlfn.XLOOKUP(H37&$T$9,disp!A:A&disp!B:B,disp!E:E))+0.25*(_xlfn.XLOOKUP(H37&$T$7,disp!A:A&disp!B:B,disp!E:E)+_xlfn.XLOOKUP(H37&$T$8,disp!A:A&disp!B:B,disp!E:E)+_xlfn.XLOOKUP(H37&$T$10,disp!A:A&disp!B:B,disp!E:E))} -> -17.275025 | N37: =ROUND(I37+J37+M37,0) -> -34 | O37: =ABS(_xlfn.FLOOR.MATH(N37,5)) -> 35 | P37: =LOOKUP(H37,Elementi!$H:$H,Elementi!$E:$E) -> 7
C38: =_xlfn.XLOOKUP(H38,Nodi!$A:$A,Nodi!$B:$B) -> -55.357368 | D38: =C38-$C$4 -> 299.8263 | E38: P06 | F38: CS-05 | H38: 560 | I38: {=_xlfn.XLOOKUP(H38&$T$11,disp!A:A&disp!B:B,disp!E:E)} -> -3.153659 | J38: {=_xlfn.XLOOKUP(H38&$T$12,disp!A:A&disp!B:B,disp!E:E)} -> 0.880672 | K38: {=(MIN(INDEX(disp!$A$2:$H$274,MATCH(1,(disp!$A$2:$A$285=OUTput_Monta_TrSx!H38)*(disp!$B$2:$B$274="Tandem_Max(min)"),0),5),INDEX(disp!$A$2:$H$274,MATCH(1,(disp!$A$2:$A$285=OUTput_Monta_TrSx!H38)*(disp!$B$2:$B$274="tandem_Ecc(min)"),0),5)))} -> #N/A | L38: {=MIN(INDEX(disp!$A$2:$H$274,MATCH(1,(disp!$A$2:$A$285=OUTput_Monta_TrSx!H38)*(disp!$B$2:$B$274="Distr_Ecc(min)"),0),5),INDEX(disp!$A$2:$H$274,MATCH(1,(disp!$A$2:$A$285=OUTput_Monta_TrSx!H38)*(disp!$B$2:$B$274="Distr_Max(min)"),0),5))} -> #N/A | M38: {=0.25*(_xlfn.XLOOKUP(H38&$T$6,disp!A:A&disp!B:B,disp!E:E)+_xlfn.XLOOKUP(H38&$T$9,disp!A:A&disp!B:B,disp!E:E))+0.25*(_xlfn.XLOOKUP(H38&$T$7,disp!A:A&disp!B:B,disp!E:E)+_xlfn.XLOOKUP(H38&$T$8,disp!A:A&disp!B:B,disp!E:E)+_xlfn.XLOOKUP(H38&$T$10,disp!A:A&disp!B:B,disp!E:E))} -> -5.0129553 | N38: =ROUND(I38+J38+M38,0) -> -7 | O38: 0 | P38: =LOOKUP(H38,Elementi!$H:$H,Elementi!$E:$E) -> 6
C39: =_xlfn.XLOOKUP(H39,Nodi!$A:$A,Nodi!$B:$B) -> -49.310061 | D39: =C39-$C$4 -> 305.87361 | H39: 554 | I39: {=_xlfn.XLOOKUP(H39&$T$11,disp!A:A&disp!B:B,disp!E:E)} -> 0 | J39: {=_xlfn.XLOOKUP(H39&$T$12,disp!A:A&disp!B:B,disp!E:E)} -> 0 | K39: {=(MIN(INDEX(disp!$A$2:$H$274,MATCH(1,(disp!$A$2:$A$285=OUTput_Monta_TrSx!H39)*(disp!$B$2:$B$274="Tandem_Max(min)"),0),5),INDEX(disp!$A$2:$H$274,MATCH(1,(disp!$A$2:$A$285=OUTput_Monta_TrSx!H39)*(disp!$B$2:$B$274="tandem_Ecc(min)"),0),5)))} -> #N/A | L39: {=MIN(INDEX(disp!$A$2:$H$274,MATCH(1,(disp!$A$2:$A$285=OUTput_Monta_TrSx!H39)*(disp!$B$2:$B$274="Distr_Ecc(min)"),0),5),INDEX(disp!$A$2:$H$274,MATCH(1,(disp!$A$2:$A$285=OUTput_Monta_TrSx!H39)*(disp!$B$2:$B$274="Distr_Max(min)"),0),5))} -> #N/A | M39: {=0.25*(_xlfn.XLOOKUP(H39&$T$6,disp!A:A&disp!B:B,disp!E:E)+_xlfn.XLOOKUP(H39&$T$9,disp!A:A&disp!B:B,disp!E:E))+0.25*(_xlfn.XLOOKUP(H39&$T$7,disp!A:A&disp!B:B,disp!E:E)+_xlfn.XLOOKUP(H39&$T$8,disp!A:A&disp!B:B,disp!E:E)+_xlfn.XLOOKUP(H39&$T$10,disp!A:A&disp!B:B,disp!E:E))} -> 0 | N39: =ROUND(I39+J39+M39,0) -> 0 | O39: =ABS(_xlfn.FLOOR.MATH(N39,5)) -> 0 | P39: =LOOKUP(H39,Elementi!$H:$H,Elementi!$E:$E) -> 5
C40: =_xlfn.XLOOKUP(H40,Nodi!$A:$A,Nodi!$B:$B) -> -43.254977 | D40: =C40-$C$4 -> 311.92869 | G40: CS-04 | H40: 547 | I40: {=_xlfn.XLOOKUP(H40&$T$11,disp!A:A&disp!B:B,disp!E:E)} -> -1.199579 | J40: {=_xlfn.XLOOKUP(H40&$T$12,disp!A:A&disp!B:B,disp!E:E)} -> -2.123323 | K40: {=(MIN(INDEX(disp!$A$2:$H$274,MATCH(1,(disp!$A$2:$A$285=OUTput_Monta_TrSx!H40)*(disp!$B$2:$B$274="Tandem_Max(min)"),0),5),INDEX(disp!$A$2:$H$274,MATCH(1,(disp!$A$2:$A$285=OUTput_Monta_TrSx!H40)*(disp!$B$2:$B$274="tandem_Ecc(min)"),0),5)))} -> #N/A | L40: {=MIN(INDEX(disp!$A$2:$H$274,MATCH(1,(disp!$A$2:$A$285=OUTput_Monta_TrSx!H40)*(disp!$B$2:$B$274="Distr_Ecc(min)"),0),5),INDEX(disp!$A$2:$H$274,MATCH(1,(disp!$A$2:$A$285=OUTput_Monta_TrSx!H40)*(disp!$B$2:$B$274="Distr_Max(min)"),0),5))} -> #N/A | M40: {=0.25*(_xlfn.XLOOKUP(H40&$T$6,disp!A:A&disp!B:B,disp!E:E)+_xlfn.XLOOKUP(H40&$T$9,disp!A:A&disp!B:B,disp!E:E))+0.25*(_xlfn.XLOOKUP(H40&$T$7,disp!A:A&disp!B:B,disp!E:E)+_xlfn.XLOOKUP(H40&$T$8,disp!A:A&disp!B:B,disp!E:E)+_xlfn.XLOOKUP(H40&$T$10,disp!A:A&disp!B:B,disp!E:E))} -> -4.6178643 | N40: =ROUND(I40+J40+M40,0) -> -8 | O40: 0 | P40: =LOOKUP(H40,Elementi!$H:$H,Elementi!$E:$E) -> 5
C41: =_xlfn.XLOOKUP(H41,Nodi!$A:$A,Nodi!$B:$B) -> -32.180948 | D41: =C41-$C$4 -> 323.00272 | F41: CS-03 | H41: 535 | I41: {=_xlfn.XLOOKUP(H41&$T$11,disp!A:A&disp!B:B,disp!E:E)} -> -7.632525 | J41: {=_xlfn.XLOOKUP(H41&$T$12,disp!A:A&disp!B:B,disp!E:E)} -> -10.166227 | K41: {=(MIN(INDEX(disp!$A$2:$H$274,MATCH(1,(disp!$A$2:$A$285=OUTput_Monta_TrSx!H41)*(disp!$B$2:$B$274="Tandem_Max(min)"),0),5),INDEX(disp!$A$2:$H$274,MATCH(1,(disp!$A$2:$A$285=OUTput_Monta_TrSx!H41)*(disp!$B$2:$B$274="tandem_Ecc(min)"),0),5)))} -> #N/A | L41: {=MIN(INDEX(disp!$A$2:$H$274,MATCH(1,(disp!$A$2:$A$285=OUTput_Monta_TrSx!H41)*(disp!$B$2:$B$274="Distr_Ecc(min)"),0),5),INDEX(disp!$A$2:$H$274,MATCH(1,(disp!$A$2:$A$285=OUTput_Monta_TrSx!H41)*(disp!$B$2:$B$274="Distr_Max(min)"),0),5))} -> #N/A | M41: {=0.25*(_xlfn.XLOOKUP(H41&$T$6,disp!A:A&disp!B:B,disp!E:E)+_xlfn.XLOOKUP(H41&$T$9,disp!A:A&disp!B:B,disp!E:E))+0.25*(_xlfn.XLOOKUP(H41&$T$7,disp!A:A&disp!B:B,disp!E:E)+_xlfn.XLOOKUP(H41&$T$8,disp!A:A&disp!B:B,disp!E:E)+_xlfn.XLOOKUP(H41&$T$10,disp!A:A&disp!B:B,disp!E:E))} -> -13.711683 | N41: =ROUND(I41+J41+M41,0) -> -32 | O41: =ABS(_xlfn.FLOOR.MATH(N41,5)) -> 35 | P41: =LOOKUP(H41,Elementi!$H:$H,Elementi!$E:$E) -> 4
...
